
    <robot name="simple_hopper">
      <link name="base">
        <visual><geometry><box size="0.2 0.2 0.2"/></geometry><material name="blue"><color rgba="0 0 1 1"/></material></visual>
        <collision><geometry><box size="0.2 0.2 0.2"/></geometry></collision>
        <inertial><mass value="1.0"/><inertia ixx="0.01" ixy="0" ixz="0" iyy="0.01" iyz="0" izz="0.01"/></inertial>
      </link>
      <link name="leg">
        <visual><origin xyz="0 0 -0.25"/><geometry><cylinder length="0.5" radius="0.05"/></geometry><material name="red"><color rgba="1 0 0 1"/></material></visual>
        <collision><origin xyz="0 0 -0.25"/><geometry><cylinder length="0.5" radius="0.05"/></geometry></collision>
        <inertial><origin xyz="0 0 -0.25"/><mass value="0.5"/><inertia ixx="0.01" ixy="0" ixz="0" iyy="0.01" iyz="0" izz="0.01"/></inertial>
      </link>
      <joint name="knee" type="revolute">
        <parent link="base"/><child link="leg"/><origin xyz="0 0 0"/><axis xyz="0 1 0"/>
        <limit effort="100" lower="-1.57" upper="1.57" velocity="10"/>
      </joint>
    </robot>
    