
    <robot name="l_leg_quad">
      <link name="base">
        <visual><geometry><box size="0.4 0.4 0.1"/></geometry><material name="blue"><color rgba="0 0 1 1"/></material></visual>
        <collision><geometry><box size="0.4 0.4 0.1"/></geometry></collision>
        <inertial><mass value="2.0"/><inertia ixx="0.1" ixy="0" ixz="0" iyy="0.1" iyz="0" izz="0.1"/></inertial>
      </link>
    
      <link name="thigh_0">
        <visual><origin xyz="0 0 -0.1"/><geometry><box size="0.05 0.05 0.2"/></geometry><material name="red"><color rgba="1 0 0 1"/></material></visual>
        <collision><origin xyz="0 0 -0.1"/><geometry><box size="0.05 0.05 0.2"/></geometry></collision>
        <inertial>
            <origin xyz="0 0 -0.1"/>
            <mass value="0.2"/>
            <inertia ixx="0.001" ixy="0" ixz="0" iyy="0.001" iyz="0" izz="0.001"/>
        </inertial>
      </link>
      <link name="calf_0">
        <visual><origin xyz="0.1 0 0"/><geometry><box size="0.2 0.05 0.05"/></geometry><material name="green"><color rgba="0 1 0 1"/></material></visual>
        <collision><origin xyz="0.1 0 0"/><geometry><box size="0.2 0.05 0.05"/></geometry></collision>
        <inertial>
            <origin xyz="0.1 0 0"/>
            <mass value="0.2"/>
            <inertia ixx="0.001" ixy="0" ixz="0" iyy="0.001" iyz="0" izz="0.001"/>
        </inertial>
      </link>
      <joint name="hip_0" type="revolute">
        <parent link="base"/><child link="thigh_0"/><origin xyz="0.2 0.2 0"/><axis xyz="0 1 0"/>
        <limit effort="100" lower="-1.5" upper="1.5" velocity="10"/>
      </joint>
      <joint name="knee_0" type="revolute">
        <parent link="thigh_0"/><child link="calf_0"/><origin xyz="0 0 -0.2"/><axis xyz="0 1 0"/>
        <limit effort="100" lower="-1.5" upper="1.5" velocity="10"/>
      </joint>
        
      <link name="thigh_1">
        <visual><origin xyz="0 0 -0.1"/><geometry><box size="0.05 0.05 0.2"/></geometry><material name="red"><color rgba="1 0 0 1"/></material></visual>
        <collision><origin xyz="0 0 -0.1"/><geometry><box size="0.05 0.05 0.2"/></geometry></collision>
        <inertial>
            <origin xyz="0 0 -0.1"/>
            <mass value="0.2"/>
            <inertia ixx="0.001" ixy="0" ixz="0" iyy="0.001" iyz="0" izz="0.001"/>
        </inertial>
      </link>
      <link name="calf_1">
        <visual><origin xyz="0.1 0 0"/><geometry><box size="0.2 0.05 0.05"/></geometry><material name="green"><color rgba="0 1 0 1"/></material></visual>
        <collision><origin xyz="0.1 0 0"/><geometry><box size="0.2 0.05 0.05"/></geometry></collision>
        <inertial>
            <origin xyz="0.1 0 0"/>
            <mass value="0.2"/>
            <inertia ixx="0.001" ixy="0" ixz="0" iyy="0.001" iyz="0" izz="0.001"/>
        </inertial>
      </link>
      <joint name="hip_1" type="revolute">
        <parent link="base"/><child link="thigh_1"/><origin xyz="0.2 -0.2 0"/><axis xyz="0 1 0"/>
        <limit effort="100" lower="-1.5" upper="1.5" velocity="10"/>
      </joint>
      <joint name="knee_1" type="revolute">
        <parent link="thigh_1"/><child link="calf_1"/><origin xyz="0 0 -0.2"/><axis xyz="0 1 0"/>
        <limit effort="100" lower="-1.5" upper="1.5" velocity="10"/>
      </joint>
        
      <link name="thigh_2">
        <visual><origin xyz="0 0 -0.1"/><geometry><box size="0.05 0.05 0.2"/></geometry><material name="red"><color rgba="1 0 0 1"/></material></visual>
        <collision><origin xyz="0 0 -0.1"/><geometry><box size="0.05 0.05 0.2"/></geometry></collision>
        <inertial>
            <origin xyz="0 0 -0.1"/>
            <mass value="0.2"/>
            <inertia ixx="0.001" ixy="0" ixz="0" iyy="0.001" iyz="0" izz="0.001"/>
        </inertial>
      </link>
      <link name="calf_2">
        <visual><origin xyz="0.1 0 0"/><geometry><box size="0.2 0.05 0.05"/></geometry><material name="green"><color rgba="0 1 0 1"/></material></visual>
        <collision><origin xyz="0.1 0 0"/><geometry><box size="0.2 0.05 0.05"/></geometry></collision>
        <inertial>
            <origin xyz="0.1 0 0"/>
            <mass value="0.2"/>
            <inertia ixx="0.001" ixy="0" ixz="0" iyy="0.001" iyz="0" izz="0.001"/>
        </inertial>
      </link>
      <joint name="hip_2" type="revolute">
        <parent link="base"/><child link="thigh_2"/><origin xyz="-0.2 0.2 0"/><axis xyz="0 1 0"/>
        <limit effort="100" lower="-1.5" upper="1.5" velocity="10"/>
      </joint>
      <joint name="knee_2" type="revolute">
        <parent link="thigh_2"/><child link="calf_2"/><origin xyz="0 0 -0.2"/><axis xyz="0 1 0"/>
        <limit effort="100" lower="-1.5" upper="1.5" velocity="10"/>
      </joint>
        
      <link name="thigh_3">
        <visual><origin xyz="0 0 -0.1"/><geometry><box size="0.05 0.05 0.2"/></geometry><material name="red"><color rgba="1 0 0 1"/></material></visual>
        <collision><origin xyz="0 0 -0.1"/><geometry><box size="0.05 0.05 0.2"/></geometry></collision>
        <inertial>
            <origin xyz="0 0 -0.1"/>
            <mass value="0.2"/>
            <inertia ixx="0.001" ixy="0" ixz="0" iyy="0.001" iyz="0" izz="0.001"/>
        </inertial>
      </link>
      <link name="calf_3">
        <visual><origin xyz="0.1 0 0"/><geometry><box size="0.2 0.05 0.05"/></geometry><material name="green"><color rgba="0 1 0 1"/></material></visual>
        <collision><origin xyz="0.1 0 0"/><geometry><box size="0.2 0.05 0.05"/></geometry></collision>
        <inertial>
            <origin xyz="0.1 0 0"/>
            <mass value="0.2"/>
            <inertia ixx="0.001" ixy="0" ixz="0" iyy="0.001" iyz="0" izz="0.001"/>
        </inertial>
      </link>
      <joint name="hip_3" type="revolute">
        <parent link="base"/><child link="thigh_3"/><origin xyz="-0.2 -0.2 0"/><axis xyz="0 1 0"/>
        <limit effort="100" lower="-1.5" upper="1.5" velocity="10"/>
      </joint>
      <joint name="knee_3" type="revolute">
        <parent link="thigh_3"/><child link="calf_3"/><origin xyz="0 0 -0.2"/><axis xyz="0 1 0"/>
        <limit effort="100" lower="-1.5" upper="1.5" velocity="10"/>
      </joint>
        </robot>